[2024-03-01 16:14:04,922][root][WARNING] - Mephisto supports rich run-time metrics visualization through Prometheus and Grafana. If you'd like to use this feature, use `mephisto metrics install` to install.(Current install dir is '/home/martins_32048/Projects/Mephisto/mephisto/scripts/metrics')'
[2024-03-01 16:14:05,095][mephisto.operations.operator][INFO] - Creating a task run under task name: react-word-sentiment
[2024-03-01 16:14:06,014][sh.command][INFO] - <Command '/usr/bin/rm -rf /home/martins_32048/mephisto-data/data/data/runs/NO_PROJECT/68/build/router', pid 1982013>: process started
[2024-03-01 16:14:07,332][sh.command][INFO] - <Command '/usr/bin/rm -rf /home/martins_32048/mephisto-data/data/data/runs/NO_PROJECT/68/build/router', pid 1982025>: process started
[2024-03-01 16:14:07,508][mephisto.abstractions.providers.prolific.api.base_api_resource][ERROR] - [Workspaces] Request error: 401 Client Error: Unauthorized for url: https://api.prolific.co/api/v1/workspaces/. Response text: `{"error":{"status":401,"title":"There was a problem during authentication.","error_code":140101,"detail":"The token provided is not valid.","additional_information":"/api/v1/errors/","interactive":false}}`
[2024-03-01 16:14:07,508][mephisto.abstractions.providers.prolific.prolific_utils][ERROR] - Could not find a workspace by title My Workspace
Traceback (most recent call last):
  File "/home/martins_32048/Projects/Mephisto/mephisto/abstractions/providers/prolific/api/base_api_resource.py", line 96, in _base_request
    response.raise_for_status()
  File "/home/martins_32048/Projects/Mephisto/venv/lib/python3.10/site-packages/requests/models.py", line 1021, in raise_for_status
    raise HTTPError(http_error_msg, response=self)
requests.exceptions.HTTPError: 401 Client Error: Unauthorized for url: https://api.prolific.co/api/v1/workspaces/

During handling of the above exception, another exception occurred:

Traceback (most recent call last):
  File "/home/martins_32048/Projects/Mephisto/mephisto/abstractions/providers/prolific/prolific_utils.py", line 135, in _find_prolific_workspace
    workspaces: List[Workspace] = client.Workspaces.list()
  File "/home/martins_32048/Projects/Mephisto/mephisto/abstractions/providers/prolific/api/workspaces.py", line 21, in list
    response_json = cls.get(cls.list_api_endpoint)
  File "/home/martins_32048/Projects/Mephisto/mephisto/abstractions/providers/prolific/api/base_api_resource.py", line 126, in get
    return cls._base_request(method, api_endpoint, params=params)
  File "/home/martins_32048/Projects/Mephisto/mephisto/abstractions/providers/prolific/api/client.py", line 39, in _base_request
    return super()._base_request(*args, **new_args)
  File "/home/martins_32048/Projects/Mephisto/mephisto/abstractions/providers/prolific/api/base_api_resource.py", line 113, in _base_request
    raise ProlificAuthenticationError
mephisto.abstractions.providers.prolific.api.exceptions.ProlificAuthenticationError
[2024-03-01 16:14:07,514][mephisto.operations.operator][ERROR] - Encountered error while launching run, shutting down
Traceback (most recent call last):
  File "/home/martins_32048/Projects/Mephisto/mephisto/abstractions/providers/prolific/api/base_api_resource.py", line 96, in _base_request
    response.raise_for_status()
  File "/home/martins_32048/Projects/Mephisto/venv/lib/python3.10/site-packages/requests/models.py", line 1021, in raise_for_status
    raise HTTPError(http_error_msg, response=self)
requests.exceptions.HTTPError: 401 Client Error: Unauthorized for url: https://api.prolific.co/api/v1/workspaces/

During handling of the above exception, another exception occurred:

Traceback (most recent call last):
  File "/home/martins_32048/Projects/Mephisto/mephisto/operations/operator.py", line 288, in launch_task_run_or_die
    live_run.provider.setup_resources_for_task_run(
  File "/home/martins_32048/Projects/Mephisto/mephisto/abstractions/providers/prolific/prolific_provider.py", line 254, in setup_resources_for_task_run
    prolific_workspace: Workspace = prolific_utils.find_or_create_prolific_workspace(
  File "/home/martins_32048/Projects/Mephisto/mephisto/abstractions/providers/prolific/prolific_utils.py", line 153, in find_or_create_prolific_workspace
    found_workspace, workspace = _find_prolific_workspace(client, title, id)
  File "/home/martins_32048/Projects/Mephisto/mephisto/abstractions/providers/prolific/prolific_utils.py", line 135, in _find_prolific_workspace
    workspaces: List[Workspace] = client.Workspaces.list()
  File "/home/martins_32048/Projects/Mephisto/mephisto/abstractions/providers/prolific/api/workspaces.py", line 21, in list
    response_json = cls.get(cls.list_api_endpoint)
  File "/home/martins_32048/Projects/Mephisto/mephisto/abstractions/providers/prolific/api/base_api_resource.py", line 126, in get
    return cls._base_request(method, api_endpoint, params=params)
  File "/home/martins_32048/Projects/Mephisto/mephisto/abstractions/providers/prolific/api/client.py", line 39, in _base_request
    return super()._base_request(*args, **new_args)
  File "/home/martins_32048/Projects/Mephisto/mephisto/abstractions/providers/prolific/api/base_api_resource.py", line 113, in _base_request
    raise ProlificAuthenticationError
mephisto.abstractions.providers.prolific.api.exceptions.ProlificAuthenticationError
[2024-03-01 16:14:07,532][sh.command][INFO] - <Command '/usr/bin/rm -rf /home/martins_32048/Projects/Mephisto/tmp/local_server_68/server', pid 1982030>: process started
[2024-03-01 16:14:07,539][mephisto.operations.operator][ERROR] - Ran into error while launching run: 
Traceback (most recent call last):
  File "/home/martins_32048/Projects/Mephisto/mephisto/abstractions/providers/prolific/api/base_api_resource.py", line 96, in _base_request
    response.raise_for_status()
  File "/home/martins_32048/Projects/Mephisto/venv/lib/python3.10/site-packages/requests/models.py", line 1021, in raise_for_status
    raise HTTPError(http_error_msg, response=self)
requests.exceptions.HTTPError: 401 Client Error: Unauthorized for url: https://api.prolific.co/api/v1/workspaces/

During handling of the above exception, another exception occurred:

Traceback (most recent call last):
  File "/home/martins_32048/Projects/Mephisto/mephisto/operations/operator.py", line 504, in launch_task_run
    return self.launch_task_run_or_die(run_config=run_config, shared_state=shared_state)
  File "/home/martins_32048/Projects/Mephisto/mephisto/operations/operator.py", line 302, in launch_task_run_or_die
    raise e
  File "/home/martins_32048/Projects/Mephisto/mephisto/operations/operator.py", line 288, in launch_task_run_or_die
    live_run.provider.setup_resources_for_task_run(
  File "/home/martins_32048/Projects/Mephisto/mephisto/abstractions/providers/prolific/prolific_provider.py", line 254, in setup_resources_for_task_run
    prolific_workspace: Workspace = prolific_utils.find_or_create_prolific_workspace(
  File "/home/martins_32048/Projects/Mephisto/mephisto/abstractions/providers/prolific/prolific_utils.py", line 153, in find_or_create_prolific_workspace
    found_workspace, workspace = _find_prolific_workspace(client, title, id)
  File "/home/martins_32048/Projects/Mephisto/mephisto/abstractions/providers/prolific/prolific_utils.py", line 135, in _find_prolific_workspace
    workspaces: List[Workspace] = client.Workspaces.list()
  File "/home/martins_32048/Projects/Mephisto/mephisto/abstractions/providers/prolific/api/workspaces.py", line 21, in list
    response_json = cls.get(cls.list_api_endpoint)
  File "/home/martins_32048/Projects/Mephisto/mephisto/abstractions/providers/prolific/api/base_api_resource.py", line 126, in get
    return cls._base_request(method, api_endpoint, params=params)
  File "/home/martins_32048/Projects/Mephisto/mephisto/abstractions/providers/prolific/api/client.py", line 39, in _base_request
    return super()._base_request(*args, **new_args)
  File "/home/martins_32048/Projects/Mephisto/mephisto/abstractions/providers/prolific/api/base_api_resource.py", line 113, in _base_request
    raise ProlificAuthenticationError
mephisto.abstractions.providers.prolific.api.exceptions.ProlificAuthenticationError
[2024-03-01 16:14:07,540][mephisto.operations.operator][INFO] - operator shutting down
[2024-03-01 16:14:17,550][mephisto.operations.operator][INFO] - Already shut down, ignoring repeated call
